[2024-07-16T10:35:20.464+0000] {task_context_logger.py:104} WARNING - Marking task instance <TaskInstance: computer_data.insert_cpu_data_task scheduled__2024-07-16T10:17:00+00:00 [queued]> stuck in queued as failed. If the task instance has available retries, it will be retried.
[2024-07-16T10:35:20.805+0000] {task_context_logger.py:104} ERROR - Executor reports task instance <TaskInstance: computer_data.insert_cpu_data_task scheduled__2024-07-16T10:17:00+00:00 [queued]> finished (failed) although the task says it's queued. (Info: None) Was the task killed externally?
